<?xml version="1.0" encoding="UTF-8"?>
<!-- Generated by org.testng.reporters.JUnitReportReporter -->
<testsuite hostname="RavindraLaptop" failures="2" tests="8" name="MyTestNG.Sept29_DP" time="0.407" errors="0" timestamp="2021-10-06T20:34:19 IST" skipped="0">
  <testcase classname="MyTestNG.Sept29_DP" name="f" time="0.008"/>
  <system-out>
Method is started Success  </system-out>
  <testcase classname="MyTestNG.Sept29_DP" name="g" time="0.064">
    <failure message="expected [-10] but found [30]" type="java.lang.AssertionError">
      <![CDATA[java.lang.AssertionError: expected [-10] but found [30]
at org.testng.Assert.fail(Assert.java:99)
at org.testng.Assert.failNotEquals(Assert.java:1037)
at org.testng.Assert.assertEqualsImpl(Assert.java:140)
at org.testng.Assert.assertEquals(Assert.java:122)
at org.testng.Assert.assertEquals(Assert.java:907)
at org.testng.Assert.assertEquals(Assert.java:917)
at MyTestNG.Sept29_DP.g(Sept29_DP.java:31)
at java.base/jdk.internal.reflect.NativeMethodAccessorImpl.invoke0(Native Method)
at java.base/jdk.internal.reflect.NativeMethodAccessorImpl.invoke(NativeMethodAccessorImpl.java:64)
at java.base/jdk.internal.reflect.DelegatingMethodAccessorImpl.invoke(DelegatingMethodAccessorImpl.java:43)
at java.base/java.lang.reflect.Method.invoke(Method.java:564)
at org.testng.internal.MethodInvocationHelper.invokeMethod(MethodInvocationHelper.java:132)
at org.testng.internal.TestInvoker.invokeMethod(TestInvoker.java:599)
at org.testng.internal.TestInvoker.invokeTestMethod(TestInvoker.java:174)
at org.testng.internal.MethodRunner.runInSequence(MethodRunner.java:46)
at org.testng.internal.TestInvoker$MethodInvocationAgent.invoke(TestInvoker.java:822)
at org.testng.internal.TestInvoker.invokeTestMethods(TestInvoker.java:147)
at org.testng.internal.TestMethodWorker.invokeTestMethods(TestMethodWorker.java:146)
at org.testng.internal.TestMethodWorker.run(TestMethodWorker.java:128)
at java.base/java.util.concurrent.ThreadPoolExecutor.runWorker(ThreadPoolExecutor.java:1130)
at java.base/java.util.concurrent.ThreadPoolExecutor$Worker.run(ThreadPoolExecutor.java:630)
at java.base/java.lang.Thread.run(Thread.java:832)
]]>
    </failure>
  </testcase> <!-- g -->
  <system-out>
Method is started Fail[TestResult name=g status=FAILURE method=Sept29_DP.g(int, int, int)[pri:0, instance:MyTestNG.Sept29_DP@5cee5251] output=Method is started]  </system-out>
  <testcase classname="MyTestNG.Sept29_DP" name="g" time="0.010">
    <failure message="expected [19] but found [21]" type="java.lang.AssertionError">
      <![CDATA[java.lang.AssertionError: expected [19] but found [21]
at org.testng.Assert.fail(Assert.java:99)
at org.testng.Assert.failNotEquals(Assert.java:1037)
at org.testng.Assert.assertEqualsImpl(Assert.java:140)
at org.testng.Assert.assertEquals(Assert.java:122)
at org.testng.Assert.assertEquals(Assert.java:907)
at org.testng.Assert.assertEquals(Assert.java:917)
at MyTestNG.Sept29_DP.g(Sept29_DP.java:31)
at java.base/jdk.internal.reflect.NativeMethodAccessorImpl.invoke0(Native Method)
at java.base/jdk.internal.reflect.NativeMethodAccessorImpl.invoke(NativeMethodAccessorImpl.java:64)
at java.base/jdk.internal.reflect.DelegatingMethodAccessorImpl.invoke(DelegatingMethodAccessorImpl.java:43)
at java.base/java.lang.reflect.Method.invoke(Method.java:564)
at org.testng.internal.MethodInvocationHelper.invokeMethod(MethodInvocationHelper.java:132)
at org.testng.internal.TestInvoker.invokeMethod(TestInvoker.java:599)
at org.testng.internal.TestInvoker.invokeTestMethod(TestInvoker.java:174)
at org.testng.internal.MethodRunner.runInSequence(MethodRunner.java:46)
at org.testng.internal.TestInvoker$MethodInvocationAgent.invoke(TestInvoker.java:822)
at org.testng.internal.TestInvoker.invokeTestMethods(TestInvoker.java:147)
at org.testng.internal.TestMethodWorker.invokeTestMethods(TestMethodWorker.java:146)
at org.testng.internal.TestMethodWorker.run(TestMethodWorker.java:128)
at java.base/java.util.concurrent.ThreadPoolExecutor.runWorker(ThreadPoolExecutor.java:1130)
at java.base/java.util.concurrent.ThreadPoolExecutor$Worker.run(ThreadPoolExecutor.java:630)
at java.base/java.lang.Thread.run(Thread.java:832)
]]>
    </failure>
  </testcase> <!-- g -->
  <system-out>
Method is started Fail[TestResult name=g status=FAILURE method=Sept29_DP.g(int, int, int)[pri:0, instance:MyTestNG.Sept29_DP@5cee5251] output=Method is started]  </system-out>
  <testcase classname="MyTestNG.Sept29_DP" name="g" time="0.024"/>
  <system-out>
Method is started Successful Success  </system-out>
  <testcase classname="MyTestNG.Sept29_DP" name="f" time="0.241"/>
  <system-out>
Method is started Success  </system-out>
  <testcase classname="MyTestNG.Sept29_DP" name="f" time="0.029"/>
  <system-out>
Method is started Success  </system-out>
  <testcase classname="MyTestNG.Sept29_DP" name="f" time="0.011"/>
  <system-out>
Method is started Success  </system-out>
  <testcase classname="MyTestNG.Sept29_DP" name="g" time="0.020"/>
  <system-out>
Method is started Successful Success  </system-out>
</testsuite> <!-- MyTestNG.Sept29_DP -->
